I'm sorry, but an uncaught exception occurred.

While running game code:
  File "game/chapter1.rpy", line 577, in script
    show natali_concerned fastdissolve
Exception: Image 'natali_concerned' does not accept attributes 'fastdissolve'.

-- Full Traceback ------------------------------------------------------------

Full traceback:
  File "game/chapter1.rpy", line 577, in script
    show natali_concerned fastdissolve
  File "E:\renpy-7.3.2-sdk to home\renpy-7.3.2-sdk\renpy\ast.py", line 1388, in execute
    show_imspec(self.imspec, atl=getattr(self, "atl", None))
  File "E:\renpy-7.3.2-sdk to home\renpy-7.3.2-sdk\renpy\ast.py", line 1351, in show_imspec
    renpy.config.show(name,
  File "E:\renpy-7.3.2-sdk to home\renpy-7.3.2-sdk\renpy\exports.py", line 686, in show
    if not base.find_target() and renpy.config.missing_show:
  File "E:\renpy-7.3.2-sdk to home\renpy-7.3.2-sdk\renpy\display\image.py", line 413, in find_target
    self.target = target._duplicate(a)
  File "E:\renpy-7.3.2-sdk to home\renpy-7.3.2-sdk\renpy\display\core.py", line 397, in _duplicate
    args.extraneous()
  File "E:\renpy-7.3.2-sdk to home\renpy-7.3.2-sdk\renpy\display\core.py", line 265, in extraneous
    raise Exception("Image '{}' does not accept attributes '{}'.".format(
Exception: Image 'natali_concerned' does not accept attributes 'fastdissolve'.

Windows-10-10.0.19044 AMD64
Ren'Py 8.0.0.22062402
Moment Of Eternity 0.03
Sun Nov 13 15:57:37 2022
